[2025-05-28 15:58:57,271] ERROR django.security.DisallowedHost: Invalid HTTP_HOST header: '127.0.0.1:8080'. You may need to add '127.0.0.1' to ALLOWED_HOSTS.
Traceback (most recent call last):
  File "C:\Users\Lanuel\Desktop\blaze-project\.venv\Lib\site-packages\django\core\handlers\exception.py", line 55, in inner
    response = get_response(request)
  File "C:\Users\Lanuel\Desktop\blaze-project\.venv\Lib\site-packages\django\utils\deprecation.py", line 119, in __call__
    response = self.process_request(request)
  File "C:\Users\Lanuel\Desktop\blaze-project\.venv\Lib\site-packages\django\middleware\common.py", line 48, in process_request
    host = request.get_host()
  File "C:\Users\Lanuel\Desktop\blaze-project\.venv\Lib\site-packages\django\http\request.py", line 186, in get_host
    raise DisallowedHost(msg)
django.core.exceptions.DisallowedHost: Invalid HTTP_HOST header: '127.0.0.1:8080'. You may need to add '127.0.0.1' to ALLOWED_HOSTS.
[2025-05-28 15:58:57,661] ERROR django.security.DisallowedHost: Invalid HTTP_HOST header: '127.0.0.1:8080'. You may need to add '127.0.0.1' to ALLOWED_HOSTS.
Traceback (most recent call last):
  File "C:\Users\Lanuel\Desktop\blaze-project\.venv\Lib\site-packages\django\core\handlers\exception.py", line 55, in inner
    response = get_response(request)
  File "C:\Users\Lanuel\Desktop\blaze-project\.venv\Lib\site-packages\django\utils\deprecation.py", line 119, in __call__
    response = self.process_request(request)
  File "C:\Users\Lanuel\Desktop\blaze-project\.venv\Lib\site-packages\django\middleware\common.py", line 48, in process_request
    host = request.get_host()
  File "C:\Users\Lanuel\Desktop\blaze-project\.venv\Lib\site-packages\django\http\request.py", line 186, in get_host
    raise DisallowedHost(msg)
django.core.exceptions.DisallowedHost: Invalid HTTP_HOST header: '127.0.0.1:8080'. You may need to add '127.0.0.1' to ALLOWED_HOSTS.
[2025-05-28 15:58:58,129] ERROR django.security.DisallowedHost: Invalid HTTP_HOST header: '127.0.0.1:8080'. You may need to add '127.0.0.1' to ALLOWED_HOSTS.
Traceback (most recent call last):
  File "C:\Users\Lanuel\Desktop\blaze-project\.venv\Lib\site-packages\django\core\handlers\exception.py", line 55, in inner
    response = get_response(request)
  File "C:\Users\Lanuel\Desktop\blaze-project\.venv\Lib\site-packages\django\utils\deprecation.py", line 119, in __call__
    response = self.process_request(request)
  File "C:\Users\Lanuel\Desktop\blaze-project\.venv\Lib\site-packages\django\middleware\common.py", line 48, in process_request
    host = request.get_host()
  File "C:\Users\Lanuel\Desktop\blaze-project\.venv\Lib\site-packages\django\http\request.py", line 186, in get_host
    raise DisallowedHost(msg)
django.core.exceptions.DisallowedHost: Invalid HTTP_HOST header: '127.0.0.1:8080'. You may need to add '127.0.0.1' to ALLOWED_HOSTS.
[2025-05-28 15:58:58,232] ERROR django.security.DisallowedHost: Invalid HTTP_HOST header: '127.0.0.1:8080'. You may need to add '127.0.0.1' to ALLOWED_HOSTS.
Traceback (most recent call last):
  File "C:\Users\Lanuel\Desktop\blaze-project\.venv\Lib\site-packages\django\core\handlers\exception.py", line 55, in inner
    response = get_response(request)
  File "C:\Users\Lanuel\Desktop\blaze-project\.venv\Lib\site-packages\django\utils\deprecation.py", line 119, in __call__
    response = self.process_request(request)
  File "C:\Users\Lanuel\Desktop\blaze-project\.venv\Lib\site-packages\django\middleware\common.py", line 48, in process_request
    host = request.get_host()
  File "C:\Users\Lanuel\Desktop\blaze-project\.venv\Lib\site-packages\django\http\request.py", line 186, in get_host
    raise DisallowedHost(msg)
django.core.exceptions.DisallowedHost: Invalid HTTP_HOST header: '127.0.0.1:8080'. You may need to add '127.0.0.1' to ALLOWED_HOSTS.
[2025-05-28 16:13:20,064] ERROR django.request: Internal Server Error: /icon/1/
Traceback (most recent call last):
  File "C:\Users\Lanuel\Desktop\blaze-project\.venv\Lib\site-packages\django\db\backends\base\base.py", line 279, in ensure_connection
    self.connect()
    ~~~~~~~~~~~~^^
  File "C:\Users\Lanuel\Desktop\blaze-project\.venv\Lib\site-packages\django\utils\asyncio.py", line 26, in inner
    return func(*args, **kwargs)
  File "C:\Users\Lanuel\Desktop\blaze-project\.venv\Lib\site-packages\django\db\backends\base\base.py", line 256, in connect
    self.connection = self.get_new_connection(conn_params)
                      ~~~~~~~~~~~~~~~~~~~~~~~^^^^^^^^^^^^^
  File "C:\Users\Lanuel\Desktop\blaze-project\.venv\Lib\site-packages\django\utils\asyncio.py", line 26, in inner
    return func(*args, **kwargs)
  File "C:\Users\Lanuel\Desktop\blaze-project\.venv\Lib\site-packages\django\db\backends\postgresql\base.py", line 332, in get_new_connection
    connection = self.Database.connect(**conn_params)
  File "C:\Users\Lanuel\Desktop\blaze-project\.venv\Lib\site-packages\psycopg2\__init__.py", line 135, in connect
    conn = _connect(dsn, connection_factory=connection_factory, **kwasync)
psycopg2.OperationalError: could not translate host name "dpg-d0ffg6juibrs73el8u9g-a.oregon-postgres.render.com" to address: Name or service not known


The above exception was the direct cause of the following exception:

Traceback (most recent call last):
  File "C:\Users\Lanuel\Desktop\blaze-project\.venv\Lib\site-packages\django\core\handlers\exception.py", line 55, in inner
    response = get_response(request)
  File "C:\Users\Lanuel\Desktop\blaze-project\.venv\Lib\site-packages\django\core\handlers\base.py", line 197, in _get_response
    response = wrapped_callback(request, *callback_args, **callback_kwargs)
  File "C:\Users\Lanuel\Desktop\blaze-project\a_home\views.py", line 30, in icon_detail
    icon = get_object_or_404(Icon, pk=icon_id)
  File "C:\Users\Lanuel\Desktop\blaze-project\.venv\Lib\site-packages\django\shortcuts.py", line 90, in get_object_or_404
    return queryset.get(*args, **kwargs)
           ~~~~~~~~~~~~^^^^^^^^^^^^^^^^^
  File "C:\Users\Lanuel\Desktop\blaze-project\.venv\Lib\site-packages\django\db\models\query.py", line 629, in get
    num = len(clone)
  File "C:\Users\Lanuel\Desktop\blaze-project\.venv\Lib\site-packages\django\db\models\query.py", line 366, in __len__
    self._fetch_all()
    ~~~~~~~~~~~~~~~^^
  File "C:\Users\Lanuel\Desktop\blaze-project\.venv\Lib\site-packages\django\db\models\query.py", line 1935, in _fetch_all
    self._result_cache = list(self._iterable_class(self))
                         ~~~~^^^^^^^^^^^^^^^^^^^^^^^^^^^^
  File "C:\Users\Lanuel\Desktop\blaze-project\.venv\Lib\site-packages\django\db\models\query.py", line 91, in __iter__
    results = compiler.execute_sql(
        chunked_fetch=self.chunked_fetch, chunk_size=self.chunk_size
    )
  File "C:\Users\Lanuel\Desktop\blaze-project\.venv\Lib\site-packages\django\db\models\sql\compiler.py", line 1620, in execute_sql
    cursor = self.connection.cursor()
  File "C:\Users\Lanuel\Desktop\blaze-project\.venv\Lib\site-packages\django\utils\asyncio.py", line 26, in inner
    return func(*args, **kwargs)
  File "C:\Users\Lanuel\Desktop\blaze-project\.venv\Lib\site-packages\django\db\backends\base\base.py", line 320, in cursor
    return self._cursor()
           ~~~~~~~~~~~~^^
  File "C:\Users\Lanuel\Desktop\blaze-project\.venv\Lib\site-packages\django\db\backends\base\base.py", line 296, in _cursor
    self.ensure_connection()
    ~~~~~~~~~~~~~~~~~~~~~~^^
  File "C:\Users\Lanuel\Desktop\blaze-project\.venv\Lib\site-packages\django\utils\asyncio.py", line 26, in inner
    return func(*args, **kwargs)
  File "C:\Users\Lanuel\Desktop\blaze-project\.venv\Lib\site-packages\django\db\backends\base\base.py", line 278, in ensure_connection
    with self.wrap_database_errors:
         ^^^^^^^^^^^^^^^^^^^^^^^^^
  File "C:\Users\Lanuel\Desktop\blaze-project\.venv\Lib\site-packages\django\db\utils.py", line 91, in __exit__
    raise dj_exc_value.with_traceback(traceback) from exc_value
  File "C:\Users\Lanuel\Desktop\blaze-project\.venv\Lib\site-packages\django\db\backends\base\base.py", line 279, in ensure_connection
    self.connect()
    ~~~~~~~~~~~~^^
  File "C:\Users\Lanuel\Desktop\blaze-project\.venv\Lib\site-packages\django\utils\asyncio.py", line 26, in inner
    return func(*args, **kwargs)
  File "C:\Users\Lanuel\Desktop\blaze-project\.venv\Lib\site-packages\django\db\backends\base\base.py", line 256, in connect
    self.connection = self.get_new_connection(conn_params)
                      ~~~~~~~~~~~~~~~~~~~~~~~^^^^^^^^^^^^^
  File "C:\Users\Lanuel\Desktop\blaze-project\.venv\Lib\site-packages\django\utils\asyncio.py", line 26, in inner
    return func(*args, **kwargs)
  File "C:\Users\Lanuel\Desktop\blaze-project\.venv\Lib\site-packages\django\db\backends\postgresql\base.py", line 332, in get_new_connection
    connection = self.Database.connect(**conn_params)
  File "C:\Users\Lanuel\Desktop\blaze-project\.venv\Lib\site-packages\psycopg2\__init__.py", line 135, in connect
    conn = _connect(dsn, connection_factory=connection_factory, **kwasync)
django.db.utils.OperationalError: could not translate host name "dpg-d0ffg6juibrs73el8u9g-a.oregon-postgres.render.com" to address: Name or service not known

[2025-05-28 16:13:20,644] ERROR django.server: "GET /icon/1/ HTTP/1.1" 500 145
[2025-05-28 16:58:19,013] ERROR django.request: Internal Server Error: /icon/1/
Traceback (most recent call last):
  File "C:\Users\Lanuel\Desktop\blaze-project\.venv\Lib\site-packages\django\db\backends\base\base.py", line 279, in ensure_connection
    self.connect()
    ~~~~~~~~~~~~^^
  File "C:\Users\Lanuel\Desktop\blaze-project\.venv\Lib\site-packages\django\utils\asyncio.py", line 26, in inner
    return func(*args, **kwargs)
  File "C:\Users\Lanuel\Desktop\blaze-project\.venv\Lib\site-packages\django\db\backends\base\base.py", line 256, in connect
    self.connection = self.get_new_connection(conn_params)
                      ~~~~~~~~~~~~~~~~~~~~~~~^^^^^^^^^^^^^
  File "C:\Users\Lanuel\Desktop\blaze-project\.venv\Lib\site-packages\django\utils\asyncio.py", line 26, in inner
    return func(*args, **kwargs)
  File "C:\Users\Lanuel\Desktop\blaze-project\.venv\Lib\site-packages\django\db\backends\postgresql\base.py", line 332, in get_new_connection
    connection = self.Database.connect(**conn_params)
  File "C:\Users\Lanuel\Desktop\blaze-project\.venv\Lib\site-packages\psycopg2\__init__.py", line 135, in connect
    conn = _connect(dsn, connection_factory=connection_factory, **kwasync)
psycopg2.OperationalError: could not translate host name "dpg-d0ffg6juibrs73el8u9g-a.oregon-postgres.render.com" to address: Name or service not known


The above exception was the direct cause of the following exception:

Traceback (most recent call last):
  File "C:\Users\Lanuel\Desktop\blaze-project\.venv\Lib\site-packages\django\core\handlers\exception.py", line 55, in inner
    response = get_response(request)
  File "C:\Users\Lanuel\Desktop\blaze-project\.venv\Lib\site-packages\django\core\handlers\base.py", line 197, in _get_response
    response = wrapped_callback(request, *callback_args, **callback_kwargs)
  File "C:\Users\Lanuel\Desktop\blaze-project\a_home\views.py", line 30, in icon_detail
    icon = get_object_or_404(Icon, pk=icon_id)
  File "C:\Users\Lanuel\Desktop\blaze-project\.venv\Lib\site-packages\django\shortcuts.py", line 90, in get_object_or_404
    return queryset.get(*args, **kwargs)
           ~~~~~~~~~~~~^^^^^^^^^^^^^^^^^
  File "C:\Users\Lanuel\Desktop\blaze-project\.venv\Lib\site-packages\django\db\models\query.py", line 629, in get
    num = len(clone)
  File "C:\Users\Lanuel\Desktop\blaze-project\.venv\Lib\site-packages\django\db\models\query.py", line 366, in __len__
    self._fetch_all()
    ~~~~~~~~~~~~~~~^^
  File "C:\Users\Lanuel\Desktop\blaze-project\.venv\Lib\site-packages\django\db\models\query.py", line 1935, in _fetch_all
    self._result_cache = list(self._iterable_class(self))
                         ~~~~^^^^^^^^^^^^^^^^^^^^^^^^^^^^
  File "C:\Users\Lanuel\Desktop\blaze-project\.venv\Lib\site-packages\django\db\models\query.py", line 91, in __iter__
    results = compiler.execute_sql(
        chunked_fetch=self.chunked_fetch, chunk_size=self.chunk_size
    )
  File "C:\Users\Lanuel\Desktop\blaze-project\.venv\Lib\site-packages\django\db\models\sql\compiler.py", line 1620, in execute_sql
    cursor = self.connection.cursor()
  File "C:\Users\Lanuel\Desktop\blaze-project\.venv\Lib\site-packages\django\utils\asyncio.py", line 26, in inner
    return func(*args, **kwargs)
  File "C:\Users\Lanuel\Desktop\blaze-project\.venv\Lib\site-packages\django\db\backends\base\base.py", line 320, in cursor
    return self._cursor()
           ~~~~~~~~~~~~^^
  File "C:\Users\Lanuel\Desktop\blaze-project\.venv\Lib\site-packages\django\db\backends\base\base.py", line 296, in _cursor
    self.ensure_connection()
    ~~~~~~~~~~~~~~~~~~~~~~^^
  File "C:\Users\Lanuel\Desktop\blaze-project\.venv\Lib\site-packages\django\utils\asyncio.py", line 26, in inner
    return func(*args, **kwargs)
  File "C:\Users\Lanuel\Desktop\blaze-project\.venv\Lib\site-packages\django\db\backends\base\base.py", line 278, in ensure_connection
    with self.wrap_database_errors:
         ^^^^^^^^^^^^^^^^^^^^^^^^^
  File "C:\Users\Lanuel\Desktop\blaze-project\.venv\Lib\site-packages\django\db\utils.py", line 91, in __exit__
    raise dj_exc_value.with_traceback(traceback) from exc_value
  File "C:\Users\Lanuel\Desktop\blaze-project\.venv\Lib\site-packages\django\db\backends\base\base.py", line 279, in ensure_connection
    self.connect()
    ~~~~~~~~~~~~^^
  File "C:\Users\Lanuel\Desktop\blaze-project\.venv\Lib\site-packages\django\utils\asyncio.py", line 26, in inner
    return func(*args, **kwargs)
  File "C:\Users\Lanuel\Desktop\blaze-project\.venv\Lib\site-packages\django\db\backends\base\base.py", line 256, in connect
    self.connection = self.get_new_connection(conn_params)
                      ~~~~~~~~~~~~~~~~~~~~~~~^^^^^^^^^^^^^
  File "C:\Users\Lanuel\Desktop\blaze-project\.venv\Lib\site-packages\django\utils\asyncio.py", line 26, in inner
    return func(*args, **kwargs)
  File "C:\Users\Lanuel\Desktop\blaze-project\.venv\Lib\site-packages\django\db\backends\postgresql\base.py", line 332, in get_new_connection
    connection = self.Database.connect(**conn_params)
  File "C:\Users\Lanuel\Desktop\blaze-project\.venv\Lib\site-packages\psycopg2\__init__.py", line 135, in connect
    conn = _connect(dsn, connection_factory=connection_factory, **kwasync)
django.db.utils.OperationalError: could not translate host name "dpg-d0ffg6juibrs73el8u9g-a.oregon-postgres.render.com" to address: Name or service not known

[2025-05-28 16:58:19,068] ERROR django.server: "GET /icon/1/ HTTP/1.1" 500 182067
[2025-06-02 15:22:09,849] ERROR django.request: Internal Server Error: /icon/19/
Traceback (most recent call last):
  File "C:\Users\Lanuel\Desktop\blaze-project\.venv\Lib\site-packages\django\template\base.py", line 510, in parse
    compile_func = self.tags[command]
                   ~~~~~~~~~^^^^^^^^^
KeyError: 'static'

During handling of the above exception, another exception occurred:

Traceback (most recent call last):
  File "C:\Users\Lanuel\Desktop\blaze-project\.venv\Lib\site-packages\django\core\handlers\exception.py", line 55, in inner
    response = get_response(request)
  File "C:\Users\Lanuel\Desktop\blaze-project\.venv\Lib\site-packages\django\core\handlers\base.py", line 197, in _get_response
    response = wrapped_callback(request, *callback_args, **callback_kwargs)
  File "C:\Users\Lanuel\Desktop\blaze-project\a_home\views.py", line 35, in icon_detail
    return render(request, 'icons/icon_detail.html', context)
  File "C:\Users\Lanuel\Desktop\blaze-project\.venv\Lib\site-packages\django\shortcuts.py", line 25, in render
    content = loader.render_to_string(template_name, context, request, using=using)
  File "C:\Users\Lanuel\Desktop\blaze-project\.venv\Lib\site-packages\django\template\loader.py", line 62, in render_to_string
    return template.render(context, request)
           ~~~~~~~~~~~~~~~^^^^^^^^^^^^^^^^^^
  File "C:\Users\Lanuel\Desktop\blaze-project\.venv\Lib\site-packages\django\template\backends\django.py", line 107, in render
    return self.template.render(context)
           ~~~~~~~~~~~~~~~~~~~~^^^^^^^^^
  File "C:\Users\Lanuel\Desktop\blaze-project\.venv\Lib\site-packages\django\template\base.py", line 171, in render
    return self._render(context)
           ~~~~~~~~~~~~^^^^^^^^^
  File "C:\Users\Lanuel\Desktop\blaze-project\.venv\Lib\site-packages\django\template\base.py", line 163, in _render
    return self.nodelist.render(context)
           ~~~~~~~~~~~~~~~~~~~~^^^^^^^^^
  File "C:\Users\Lanuel\Desktop\blaze-project\.venv\Lib\site-packages\django\template\base.py", line 1016, in render
    return SafeString("".join([node.render_annotated(context) for node in self]))
                               ~~~~~~~~~~~~~~~~~~~~~^^^^^^^^^
  File "C:\Users\Lanuel\Desktop\blaze-project\.venv\Lib\site-packages\django\template\base.py", line 977, in render_annotated
    return self.render(context)
           ~~~~~~~~~~~^^^^^^^^^
  File "C:\Users\Lanuel\Desktop\blaze-project\.venv\Lib\site-packages\django\template\loader_tags.py", line 159, in render
    return compiled_parent._render(context)
           ~~~~~~~~~~~~~~~~~~~~~~~^^^^^^^^^
  File "C:\Users\Lanuel\Desktop\blaze-project\.venv\Lib\site-packages\django\template\base.py", line 163, in _render
    return self.nodelist.render(context)
           ~~~~~~~~~~~~~~~~~~~~^^^^^^^^^
  File "C:\Users\Lanuel\Desktop\blaze-project\.venv\Lib\site-packages\django\template\base.py", line 1016, in render
    return SafeString("".join([node.render_annotated(context) for node in self]))
                               ~~~~~~~~~~~~~~~~~~~~~^^^^^^^^^
  File "C:\Users\Lanuel\Desktop\blaze-project\.venv\Lib\site-packages\django\template\base.py", line 977, in render_annotated
    return self.render(context)
           ~~~~~~~~~~~^^^^^^^^^
  File "C:\Users\Lanuel\Desktop\blaze-project\.venv\Lib\site-packages\django\template\loader_tags.py", line 65, in render
    result = block.nodelist.render(context)
  File "C:\Users\Lanuel\Desktop\blaze-project\.venv\Lib\site-packages\django\template\base.py", line 1016, in render
    return SafeString("".join([node.render_annotated(context) for node in self]))
                               ~~~~~~~~~~~~~~~~~~~~~^^^^^^^^^
  File "C:\Users\Lanuel\Desktop\blaze-project\.venv\Lib\site-packages\django\template\base.py", line 977, in render_annotated
    return self.render(context)
           ~~~~~~~~~~~^^^^^^^^^
  File "C:\Users\Lanuel\Desktop\blaze-project\.venv\Lib\site-packages\django\template\loader_tags.py", line 199, in render
    template = context.template.engine.select_template(template_name)
  File "C:\Users\Lanuel\Desktop\blaze-project\.venv\Lib\site-packages\django\template\engine.py", line 208, in select_template
    return self.get_template(template_name)
           ~~~~~~~~~~~~~~~~~^^^^^^^^^^^^^^^
  File "C:\Users\Lanuel\Desktop\blaze-project\.venv\Lib\site-packages\django\template\engine.py", line 177, in get_template
    template, origin = self.find_template(template_name)
                       ~~~~~~~~~~~~~~~~~~^^^^^^^^^^^^^^^
  File "C:\Users\Lanuel\Desktop\blaze-project\.venv\Lib\site-packages\django\template\engine.py", line 159, in find_template
    template = loader.get_template(name, skip=skip)
  File "C:\Users\Lanuel\Desktop\blaze-project\.venv\Lib\site-packages\django\template\loaders\cached.py", line 57, in get_template
    template = super().get_template(template_name, skip)
  File "C:\Users\Lanuel\Desktop\blaze-project\.venv\Lib\site-packages\django\template\loaders\base.py", line 28, in get_template
    return Template(
        contents,
    ...<2 lines>...
        self.engine,
    )
  File "C:\Users\Lanuel\Desktop\blaze-project\.venv\Lib\site-packages\django\template\base.py", line 154, in __init__
    self.nodelist = self.compile_nodelist()
                    ~~~~~~~~~~~~~~~~~~~~~^^
  File "C:\Users\Lanuel\Desktop\blaze-project\.venv\Lib\site-packages\django\template\base.py", line 196, in compile_nodelist
    nodelist = parser.parse()
  File "C:\Users\Lanuel\Desktop\blaze-project\.venv\Lib\site-packages\django\template\base.py", line 512, in parse
    self.invalid_block_tag(token, command, parse_until)
    ~~~~~~~~~~~~~~~~~~~~~~^^^^^^^^^^^^^^^^^^^^^^^^^^^^^
  File "C:\Users\Lanuel\Desktop\blaze-project\.venv\Lib\site-packages\django\template\base.py", line 577, in invalid_block_tag
    raise self.error(
    ...<3 lines>...
    )
django.template.exceptions.TemplateSyntaxError: Invalid block tag on line 284: 'static'. Did you forget to register or load this tag?
[2025-06-02 15:22:09,948] ERROR django.server: "GET /icon/19/ HTTP/1.1" 500 210044
