[2025-05-28 15:58:57,271] ERROR django.security.DisallowedHost: Invalid HTTP_HOST header: '127.0.0.1:8080'. You may need to add '127.0.0.1' to ALLOWED_HOSTS.
Traceback (most recent call last):
  File "C:\Users\Lanuel\Desktop\blaze-project\.venv\Lib\site-packages\django\core\handlers\exception.py", line 55, in inner
    response = get_response(request)
  File "C:\Users\Lanuel\Desktop\blaze-project\.venv\Lib\site-packages\django\utils\deprecation.py", line 119, in __call__
    response = self.process_request(request)
  File "C:\Users\Lanuel\Desktop\blaze-project\.venv\Lib\site-packages\django\middleware\common.py", line 48, in process_request
    host = request.get_host()
  File "C:\Users\Lanuel\Desktop\blaze-project\.venv\Lib\site-packages\django\http\request.py", line 186, in get_host
    raise DisallowedHost(msg)
django.core.exceptions.DisallowedHost: Invalid HTTP_HOST header: '127.0.0.1:8080'. You may need to add '127.0.0.1' to ALLOWED_HOSTS.
[2025-05-28 15:58:57,661] ERROR django.security.DisallowedHost: Invalid HTTP_HOST header: '127.0.0.1:8080'. You may need to add '127.0.0.1' to ALLOWED_HOSTS.
Traceback (most recent call last):
  File "C:\Users\Lanuel\Desktop\blaze-project\.venv\Lib\site-packages\django\core\handlers\exception.py", line 55, in inner
    response = get_response(request)
  File "C:\Users\Lanuel\Desktop\blaze-project\.venv\Lib\site-packages\django\utils\deprecation.py", line 119, in __call__
    response = self.process_request(request)
  File "C:\Users\Lanuel\Desktop\blaze-project\.venv\Lib\site-packages\django\middleware\common.py", line 48, in process_request
    host = request.get_host()
  File "C:\Users\Lanuel\Desktop\blaze-project\.venv\Lib\site-packages\django\http\request.py", line 186, in get_host
    raise DisallowedHost(msg)
django.core.exceptions.DisallowedHost: Invalid HTTP_HOST header: '127.0.0.1:8080'. You may need to add '127.0.0.1' to ALLOWED_HOSTS.
[2025-05-28 15:58:58,129] ERROR django.security.DisallowedHost: Invalid HTTP_HOST header: '127.0.0.1:8080'. You may need to add '127.0.0.1' to ALLOWED_HOSTS.
Traceback (most recent call last):
  File "C:\Users\Lanuel\Desktop\blaze-project\.venv\Lib\site-packages\django\core\handlers\exception.py", line 55, in inner
    response = get_response(request)
  File "C:\Users\Lanuel\Desktop\blaze-project\.venv\Lib\site-packages\django\utils\deprecation.py", line 119, in __call__
    response = self.process_request(request)
  File "C:\Users\Lanuel\Desktop\blaze-project\.venv\Lib\site-packages\django\middleware\common.py", line 48, in process_request
    host = request.get_host()
  File "C:\Users\Lanuel\Desktop\blaze-project\.venv\Lib\site-packages\django\http\request.py", line 186, in get_host
    raise DisallowedHost(msg)
django.core.exceptions.DisallowedHost: Invalid HTTP_HOST header: '127.0.0.1:8080'. You may need to add '127.0.0.1' to ALLOWED_HOSTS.
[2025-05-28 15:58:58,232] ERROR django.security.DisallowedHost: Invalid HTTP_HOST header: '127.0.0.1:8080'. You may need to add '127.0.0.1' to ALLOWED_HOSTS.
Traceback (most recent call last):
  File "C:\Users\Lanuel\Desktop\blaze-project\.venv\Lib\site-packages\django\core\handlers\exception.py", line 55, in inner
    response = get_response(request)
  File "C:\Users\Lanuel\Desktop\blaze-project\.venv\Lib\site-packages\django\utils\deprecation.py", line 119, in __call__
    response = self.process_request(request)
  File "C:\Users\Lanuel\Desktop\blaze-project\.venv\Lib\site-packages\django\middleware\common.py", line 48, in process_request
    host = request.get_host()
  File "C:\Users\Lanuel\Desktop\blaze-project\.venv\Lib\site-packages\django\http\request.py", line 186, in get_host
    raise DisallowedHost(msg)
django.core.exceptions.DisallowedHost: Invalid HTTP_HOST header: '127.0.0.1:8080'. You may need to add '127.0.0.1' to ALLOWED_HOSTS.
[2025-05-28 16:13:20,064] ERROR django.request: Internal Server Error: /icon/1/
Traceback (most recent call last):
  File "C:\Users\Lanuel\Desktop\blaze-project\.venv\Lib\site-packages\django\db\backends\base\base.py", line 279, in ensure_connection
    self.connect()
    ~~~~~~~~~~~~^^
  File "C:\Users\Lanuel\Desktop\blaze-project\.venv\Lib\site-packages\django\utils\asyncio.py", line 26, in inner
    return func(*args, **kwargs)
  File "C:\Users\Lanuel\Desktop\blaze-project\.venv\Lib\site-packages\django\db\backends\base\base.py", line 256, in connect
    self.connection = self.get_new_connection(conn_params)
                      ~~~~~~~~~~~~~~~~~~~~~~~^^^^^^^^^^^^^
  File "C:\Users\Lanuel\Desktop\blaze-project\.venv\Lib\site-packages\django\utils\asyncio.py", line 26, in inner
    return func(*args, **kwargs)
  File "C:\Users\Lanuel\Desktop\blaze-project\.venv\Lib\site-packages\django\db\backends\postgresql\base.py", line 332, in get_new_connection
    connection = self.Database.connect(**conn_params)
  File "C:\Users\Lanuel\Desktop\blaze-project\.venv\Lib\site-packages\psycopg2\__init__.py", line 135, in connect
    conn = _connect(dsn, connection_factory=connection_factory, **kwasync)
psycopg2.OperationalError: could not translate host name "dpg-d0ffg6juibrs73el8u9g-a.oregon-postgres.render.com" to address: Name or service not known


The above exception was the direct cause of the following exception:

Traceback (most recent call last):
  File "C:\Users\Lanuel\Desktop\blaze-project\.venv\Lib\site-packages\django\core\handlers\exception.py", line 55, in inner
    response = get_response(request)
  File "C:\Users\Lanuel\Desktop\blaze-project\.venv\Lib\site-packages\django\core\handlers\base.py", line 197, in _get_response
    response = wrapped_callback(request, *callback_args, **callback_kwargs)
  File "C:\Users\Lanuel\Desktop\blaze-project\a_home\views.py", line 30, in icon_detail
    icon = get_object_or_404(Icon, pk=icon_id)
  File "C:\Users\Lanuel\Desktop\blaze-project\.venv\Lib\site-packages\django\shortcuts.py", line 90, in get_object_or_404
    return queryset.get(*args, **kwargs)
           ~~~~~~~~~~~~^^^^^^^^^^^^^^^^^
  File "C:\Users\Lanuel\Desktop\blaze-project\.venv\Lib\site-packages\django\db\models\query.py", line 629, in get
    num = len(clone)
  File "C:\Users\Lanuel\Desktop\blaze-project\.venv\Lib\site-packages\django\db\models\query.py", line 366, in __len__
    self._fetch_all()
    ~~~~~~~~~~~~~~~^^
  File "C:\Users\Lanuel\Desktop\blaze-project\.venv\Lib\site-packages\django\db\models\query.py", line 1935, in _fetch_all
    self._result_cache = list(self._iterable_class(self))
                         ~~~~^^^^^^^^^^^^^^^^^^^^^^^^^^^^
  File "C:\Users\Lanuel\Desktop\blaze-project\.venv\Lib\site-packages\django\db\models\query.py", line 91, in __iter__
    results = compiler.execute_sql(
        chunked_fetch=self.chunked_fetch, chunk_size=self.chunk_size
    )
  File "C:\Users\Lanuel\Desktop\blaze-project\.venv\Lib\site-packages\django\db\models\sql\compiler.py", line 1620, in execute_sql
    cursor = self.connection.cursor()
  File "C:\Users\Lanuel\Desktop\blaze-project\.venv\Lib\site-packages\django\utils\asyncio.py", line 26, in inner
    return func(*args, **kwargs)
  File "C:\Users\Lanuel\Desktop\blaze-project\.venv\Lib\site-packages\django\db\backends\base\base.py", line 320, in cursor
    return self._cursor()
           ~~~~~~~~~~~~^^
  File "C:\Users\Lanuel\Desktop\blaze-project\.venv\Lib\site-packages\django\db\backends\base\base.py", line 296, in _cursor
    self.ensure_connection()
    ~~~~~~~~~~~~~~~~~~~~~~^^
  File "C:\Users\Lanuel\Desktop\blaze-project\.venv\Lib\site-packages\django\utils\asyncio.py", line 26, in inner
    return func(*args, **kwargs)
  File "C:\Users\Lanuel\Desktop\blaze-project\.venv\Lib\site-packages\django\db\backends\base\base.py", line 278, in ensure_connection
    with self.wrap_database_errors:
         ^^^^^^^^^^^^^^^^^^^^^^^^^
  File "C:\Users\Lanuel\Desktop\blaze-project\.venv\Lib\site-packages\django\db\utils.py", line 91, in __exit__
    raise dj_exc_value.with_traceback(traceback) from exc_value
  File "C:\Users\Lanuel\Desktop\blaze-project\.venv\Lib\site-packages\django\db\backends\base\base.py", line 279, in ensure_connection
    self.connect()
    ~~~~~~~~~~~~^^
  File "C:\Users\Lanuel\Desktop\blaze-project\.venv\Lib\site-packages\django\utils\asyncio.py", line 26, in inner
    return func(*args, **kwargs)
  File "C:\Users\Lanuel\Desktop\blaze-project\.venv\Lib\site-packages\django\db\backends\base\base.py", line 256, in connect
    self.connection = self.get_new_connection(conn_params)
                      ~~~~~~~~~~~~~~~~~~~~~~~^^^^^^^^^^^^^
  File "C:\Users\Lanuel\Desktop\blaze-project\.venv\Lib\site-packages\django\utils\asyncio.py", line 26, in inner
    return func(*args, **kwargs)
  File "C:\Users\Lanuel\Desktop\blaze-project\.venv\Lib\site-packages\django\db\backends\postgresql\base.py", line 332, in get_new_connection
    connection = self.Database.connect(**conn_params)
  File "C:\Users\Lanuel\Desktop\blaze-project\.venv\Lib\site-packages\psycopg2\__init__.py", line 135, in connect
    conn = _connect(dsn, connection_factory=connection_factory, **kwasync)
django.db.utils.OperationalError: could not translate host name "dpg-d0ffg6juibrs73el8u9g-a.oregon-postgres.render.com" to address: Name or service not known

[2025-05-28 16:13:20,644] ERROR django.server: "GET /icon/1/ HTTP/1.1" 500 145
[2025-05-28 16:58:19,013] ERROR django.request: Internal Server Error: /icon/1/
Traceback (most recent call last):
  File "C:\Users\Lanuel\Desktop\blaze-project\.venv\Lib\site-packages\django\db\backends\base\base.py", line 279, in ensure_connection
    self.connect()
    ~~~~~~~~~~~~^^
  File "C:\Users\Lanuel\Desktop\blaze-project\.venv\Lib\site-packages\django\utils\asyncio.py", line 26, in inner
    return func(*args, **kwargs)
  File "C:\Users\Lanuel\Desktop\blaze-project\.venv\Lib\site-packages\django\db\backends\base\base.py", line 256, in connect
    self.connection = self.get_new_connection(conn_params)
                      ~~~~~~~~~~~~~~~~~~~~~~~^^^^^^^^^^^^^
  File "C:\Users\Lanuel\Desktop\blaze-project\.venv\Lib\site-packages\django\utils\asyncio.py", line 26, in inner
    return func(*args, **kwargs)
  File "C:\Users\Lanuel\Desktop\blaze-project\.venv\Lib\site-packages\django\db\backends\postgresql\base.py", line 332, in get_new_connection
    connection = self.Database.connect(**conn_params)
  File "C:\Users\Lanuel\Desktop\blaze-project\.venv\Lib\site-packages\psycopg2\__init__.py", line 135, in connect
    conn = _connect(dsn, connection_factory=connection_factory, **kwasync)
psycopg2.OperationalError: could not translate host name "dpg-d0ffg6juibrs73el8u9g-a.oregon-postgres.render.com" to address: Name or service not known


The above exception was the direct cause of the following exception:

Traceback (most recent call last):
  File "C:\Users\Lanuel\Desktop\blaze-project\.venv\Lib\site-packages\django\core\handlers\exception.py", line 55, in inner
    response = get_response(request)
  File "C:\Users\Lanuel\Desktop\blaze-project\.venv\Lib\site-packages\django\core\handlers\base.py", line 197, in _get_response
    response = wrapped_callback(request, *callback_args, **callback_kwargs)
  File "C:\Users\Lanuel\Desktop\blaze-project\a_home\views.py", line 30, in icon_detail
    icon = get_object_or_404(Icon, pk=icon_id)
  File "C:\Users\Lanuel\Desktop\blaze-project\.venv\Lib\site-packages\django\shortcuts.py", line 90, in get_object_or_404
    return queryset.get(*args, **kwargs)
           ~~~~~~~~~~~~^^^^^^^^^^^^^^^^^
  File "C:\Users\Lanuel\Desktop\blaze-project\.venv\Lib\site-packages\django\db\models\query.py", line 629, in get
    num = len(clone)
  File "C:\Users\Lanuel\Desktop\blaze-project\.venv\Lib\site-packages\django\db\models\query.py", line 366, in __len__
    self._fetch_all()
    ~~~~~~~~~~~~~~~^^
  File "C:\Users\Lanuel\Desktop\blaze-project\.venv\Lib\site-packages\django\db\models\query.py", line 1935, in _fetch_all
    self._result_cache = list(self._iterable_class(self))
                         ~~~~^^^^^^^^^^^^^^^^^^^^^^^^^^^^
  File "C:\Users\Lanuel\Desktop\blaze-project\.venv\Lib\site-packages\django\db\models\query.py", line 91, in __iter__
    results = compiler.execute_sql(
        chunked_fetch=self.chunked_fetch, chunk_size=self.chunk_size
    )
  File "C:\Users\Lanuel\Desktop\blaze-project\.venv\Lib\site-packages\django\db\models\sql\compiler.py", line 1620, in execute_sql
    cursor = self.connection.cursor()
  File "C:\Users\Lanuel\Desktop\blaze-project\.venv\Lib\site-packages\django\utils\asyncio.py", line 26, in inner
    return func(*args, **kwargs)
  File "C:\Users\Lanuel\Desktop\blaze-project\.venv\Lib\site-packages\django\db\backends\base\base.py", line 320, in cursor
    return self._cursor()
           ~~~~~~~~~~~~^^
  File "C:\Users\Lanuel\Desktop\blaze-project\.venv\Lib\site-packages\django\db\backends\base\base.py", line 296, in _cursor
    self.ensure_connection()
    ~~~~~~~~~~~~~~~~~~~~~~^^
  File "C:\Users\Lanuel\Desktop\blaze-project\.venv\Lib\site-packages\django\utils\asyncio.py", line 26, in inner
    return func(*args, **kwargs)
  File "C:\Users\Lanuel\Desktop\blaze-project\.venv\Lib\site-packages\django\db\backends\base\base.py", line 278, in ensure_connection
    with self.wrap_database_errors:
         ^^^^^^^^^^^^^^^^^^^^^^^^^
  File "C:\Users\Lanuel\Desktop\blaze-project\.venv\Lib\site-packages\django\db\utils.py", line 91, in __exit__
    raise dj_exc_value.with_traceback(traceback) from exc_value
  File "C:\Users\Lanuel\Desktop\blaze-project\.venv\Lib\site-packages\django\db\backends\base\base.py", line 279, in ensure_connection
    self.connect()
    ~~~~~~~~~~~~^^
  File "C:\Users\Lanuel\Desktop\blaze-project\.venv\Lib\site-packages\django\utils\asyncio.py", line 26, in inner
    return func(*args, **kwargs)
  File "C:\Users\Lanuel\Desktop\blaze-project\.venv\Lib\site-packages\django\db\backends\base\base.py", line 256, in connect
    self.connection = self.get_new_connection(conn_params)
                      ~~~~~~~~~~~~~~~~~~~~~~~^^^^^^^^^^^^^
  File "C:\Users\Lanuel\Desktop\blaze-project\.venv\Lib\site-packages\django\utils\asyncio.py", line 26, in inner
    return func(*args, **kwargs)
  File "C:\Users\Lanuel\Desktop\blaze-project\.venv\Lib\site-packages\django\db\backends\postgresql\base.py", line 332, in get_new_connection
    connection = self.Database.connect(**conn_params)
  File "C:\Users\Lanuel\Desktop\blaze-project\.venv\Lib\site-packages\psycopg2\__init__.py", line 135, in connect
    conn = _connect(dsn, connection_factory=connection_factory, **kwasync)
django.db.utils.OperationalError: could not translate host name "dpg-d0ffg6juibrs73el8u9g-a.oregon-postgres.render.com" to address: Name or service not known

[2025-05-28 16:58:19,068] ERROR django.server: "GET /icon/1/ HTTP/1.1" 500 182067
[2025-06-02 15:22:09,849] ERROR django.request: Internal Server Error: /icon/19/
Traceback (most recent call last):
  File "C:\Users\Lanuel\Desktop\blaze-project\.venv\Lib\site-packages\django\template\base.py", line 510, in parse
    compile_func = self.tags[command]
                   ~~~~~~~~~^^^^^^^^^
KeyError: 'static'

During handling of the above exception, another exception occurred:

Traceback (most recent call last):
  File "C:\Users\Lanuel\Desktop\blaze-project\.venv\Lib\site-packages\django\core\handlers\exception.py", line 55, in inner
    response = get_response(request)
  File "C:\Users\Lanuel\Desktop\blaze-project\.venv\Lib\site-packages\django\core\handlers\base.py", line 197, in _get_response
    response = wrapped_callback(request, *callback_args, **callback_kwargs)
  File "C:\Users\Lanuel\Desktop\blaze-project\a_home\views.py", line 35, in icon_detail
    return render(request, 'icons/icon_detail.html', context)
  File "C:\Users\Lanuel\Desktop\blaze-project\.venv\Lib\site-packages\django\shortcuts.py", line 25, in render
    content = loader.render_to_string(template_name, context, request, using=using)
  File "C:\Users\Lanuel\Desktop\blaze-project\.venv\Lib\site-packages\django\template\loader.py", line 62, in render_to_string
    return template.render(context, request)
           ~~~~~~~~~~~~~~~^^^^^^^^^^^^^^^^^^
  File "C:\Users\Lanuel\Desktop\blaze-project\.venv\Lib\site-packages\django\template\backends\django.py", line 107, in render
    return self.template.render(context)
           ~~~~~~~~~~~~~~~~~~~~^^^^^^^^^
  File "C:\Users\Lanuel\Desktop\blaze-project\.venv\Lib\site-packages\django\template\base.py", line 171, in render
    return self._render(context)
           ~~~~~~~~~~~~^^^^^^^^^
  File "C:\Users\Lanuel\Desktop\blaze-project\.venv\Lib\site-packages\django\template\base.py", line 163, in _render
    return self.nodelist.render(context)
           ~~~~~~~~~~~~~~~~~~~~^^^^^^^^^
  File "C:\Users\Lanuel\Desktop\blaze-project\.venv\Lib\site-packages\django\template\base.py", line 1016, in render
    return SafeString("".join([node.render_annotated(context) for node in self]))
                               ~~~~~~~~~~~~~~~~~~~~~^^^^^^^^^
  File "C:\Users\Lanuel\Desktop\blaze-project\.venv\Lib\site-packages\django\template\base.py", line 977, in render_annotated
    return self.render(context)
           ~~~~~~~~~~~^^^^^^^^^
  File "C:\Users\Lanuel\Desktop\blaze-project\.venv\Lib\site-packages\django\template\loader_tags.py", line 159, in render
    return compiled_parent._render(context)
           ~~~~~~~~~~~~~~~~~~~~~~~^^^^^^^^^
  File "C:\Users\Lanuel\Desktop\blaze-project\.venv\Lib\site-packages\django\template\base.py", line 163, in _render
    return self.nodelist.render(context)
           ~~~~~~~~~~~~~~~~~~~~^^^^^^^^^
  File "C:\Users\Lanuel\Desktop\blaze-project\.venv\Lib\site-packages\django\template\base.py", line 1016, in render
    return SafeString("".join([node.render_annotated(context) for node in self]))
                               ~~~~~~~~~~~~~~~~~~~~~^^^^^^^^^
  File "C:\Users\Lanuel\Desktop\blaze-project\.venv\Lib\site-packages\django\template\base.py", line 977, in render_annotated
    return self.render(context)
           ~~~~~~~~~~~^^^^^^^^^
  File "C:\Users\Lanuel\Desktop\blaze-project\.venv\Lib\site-packages\django\template\loader_tags.py", line 65, in render
    result = block.nodelist.render(context)
  File "C:\Users\Lanuel\Desktop\blaze-project\.venv\Lib\site-packages\django\template\base.py", line 1016, in render
    return SafeString("".join([node.render_annotated(context) for node in self]))
                               ~~~~~~~~~~~~~~~~~~~~~^^^^^^^^^
  File "C:\Users\Lanuel\Desktop\blaze-project\.venv\Lib\site-packages\django\template\base.py", line 977, in render_annotated
    return self.render(context)
           ~~~~~~~~~~~^^^^^^^^^
  File "C:\Users\Lanuel\Desktop\blaze-project\.venv\Lib\site-packages\django\template\loader_tags.py", line 199, in render
    template = context.template.engine.select_template(template_name)
  File "C:\Users\Lanuel\Desktop\blaze-project\.venv\Lib\site-packages\django\template\engine.py", line 208, in select_template
    return self.get_template(template_name)
           ~~~~~~~~~~~~~~~~~^^^^^^^^^^^^^^^
  File "C:\Users\Lanuel\Desktop\blaze-project\.venv\Lib\site-packages\django\template\engine.py", line 177, in get_template
    template, origin = self.find_template(template_name)
                       ~~~~~~~~~~~~~~~~~~^^^^^^^^^^^^^^^
  File "C:\Users\Lanuel\Desktop\blaze-project\.venv\Lib\site-packages\django\template\engine.py", line 159, in find_template
    template = loader.get_template(name, skip=skip)
  File "C:\Users\Lanuel\Desktop\blaze-project\.venv\Lib\site-packages\django\template\loaders\cached.py", line 57, in get_template
    template = super().get_template(template_name, skip)
  File "C:\Users\Lanuel\Desktop\blaze-project\.venv\Lib\site-packages\django\template\loaders\base.py", line 28, in get_template
    return Template(
        contents,
    ...<2 lines>...
        self.engine,
    )
  File "C:\Users\Lanuel\Desktop\blaze-project\.venv\Lib\site-packages\django\template\base.py", line 154, in __init__
    self.nodelist = self.compile_nodelist()
                    ~~~~~~~~~~~~~~~~~~~~~^^
  File "C:\Users\Lanuel\Desktop\blaze-project\.venv\Lib\site-packages\django\template\base.py", line 196, in compile_nodelist
    nodelist = parser.parse()
  File "C:\Users\Lanuel\Desktop\blaze-project\.venv\Lib\site-packages\django\template\base.py", line 512, in parse
    self.invalid_block_tag(token, command, parse_until)
    ~~~~~~~~~~~~~~~~~~~~~~^^^^^^^^^^^^^^^^^^^^^^^^^^^^^
  File "C:\Users\Lanuel\Desktop\blaze-project\.venv\Lib\site-packages\django\template\base.py", line 577, in invalid_block_tag
    raise self.error(
    ...<3 lines>...
    )
django.template.exceptions.TemplateSyntaxError: Invalid block tag on line 284: 'static'. Did you forget to register or load this tag?
[2025-06-02 15:22:09,948] ERROR django.server: "GET /icon/19/ HTTP/1.1" 500 210044
[2025-06-02 21:24:29,959] ERROR django.request: Internal Server Error: /3vablazin/a_home/icon/add/
Traceback (most recent call last):
  File "C:\Users\Lanuel\Desktop\blaze-project\.venv\Lib\site-packages\urllib3\connectionpool.py", line 534, in _make_request
    response = conn.getresponse()
  File "C:\Users\Lanuel\Desktop\blaze-project\.venv\Lib\site-packages\urllib3\connection.py", line 516, in getresponse
    httplib_response = super().getresponse()
  File "C:\Users\Lanuel\AppData\Local\Programs\Python\Python313\Lib\http\client.py", line 1430, in getresponse
    response.begin()
    ~~~~~~~~~~~~~~^^
  File "C:\Users\Lanuel\AppData\Local\Programs\Python\Python313\Lib\http\client.py", line 331, in begin
    version, status, reason = self._read_status()
                              ~~~~~~~~~~~~~~~~~^^
  File "C:\Users\Lanuel\AppData\Local\Programs\Python\Python313\Lib\http\client.py", line 292, in _read_status
    line = str(self.fp.readline(_MAXLINE + 1), "iso-8859-1")
               ~~~~~~~~~~~~~~~~^^^^^^^^^^^^^^
  File "C:\Users\Lanuel\AppData\Local\Programs\Python\Python313\Lib\socket.py", line 719, in readinto
    return self._sock.recv_into(b)
           ~~~~~~~~~~~~~~~~~~~~^^^
  File "C:\Users\Lanuel\AppData\Local\Programs\Python\Python313\Lib\ssl.py", line 1304, in recv_into
    return self.read(nbytes, buffer)
           ~~~~~~~~~^^^^^^^^^^^^^^^^
  File "C:\Users\Lanuel\AppData\Local\Programs\Python\Python313\Lib\ssl.py", line 1138, in read
    return self._sslobj.read(len, buffer)
           ~~~~~~~~~~~~~~~~~^^^^^^^^^^^^^
TimeoutError: [WinError 10060] A connection attempt failed because the connected party did not properly respond after a period of time, or established connection failed because connected host has failed to respond

The above exception was the direct cause of the following exception:

Traceback (most recent call last):
  File "C:\Users\Lanuel\Desktop\blaze-project\.venv\Lib\site-packages\cloudinary\uploader.py", line 903, in call_api
    response = _http.request(method="POST", url=api_url, fields=param_list, headers=headers, **kw)
  File "C:\Users\Lanuel\Desktop\blaze-project\.venv\Lib\site-packages\urllib3\_request_methods.py", line 143, in request
    return self.request_encode_body(
           ~~~~~~~~~~~~~~~~~~~~~~~~^
        method, url, fields=fields, headers=headers, **urlopen_kw
        ^^^^^^^^^^^^^^^^^^^^^^^^^^^^^^^^^^^^^^^^^^^^^^^^^^^^^^^^^
    )
    ^
  File "C:\Users\Lanuel\Desktop\blaze-project\.venv\Lib\site-packages\urllib3\_request_methods.py", line 278, in request_encode_body
    return self.urlopen(method, url, **extra_kw)
           ~~~~~~~~~~~~^^^^^^^^^^^^^^^^^^^^^^^^^
  File "C:\Users\Lanuel\Desktop\blaze-project\.venv\Lib\site-packages\urllib3\poolmanager.py", line 443, in urlopen
    response = conn.urlopen(method, u.request_uri, **kw)
  File "C:\Users\Lanuel\Desktop\blaze-project\.venv\Lib\site-packages\urllib3\connectionpool.py", line 841, in urlopen
    retries = retries.increment(
        method, url, error=new_e, _pool=self, _stacktrace=sys.exc_info()[2]
    )
  File "C:\Users\Lanuel\Desktop\blaze-project\.venv\Lib\site-packages\urllib3\util\retry.py", line 474, in increment
    raise reraise(type(error), error, _stacktrace)
          ~~~~~~~^^^^^^^^^^^^^^^^^^^^^^^^^^^^^^^^^
  File "C:\Users\Lanuel\Desktop\blaze-project\.venv\Lib\site-packages\urllib3\util\util.py", line 39, in reraise
    raise value
  File "C:\Users\Lanuel\Desktop\blaze-project\.venv\Lib\site-packages\urllib3\connectionpool.py", line 787, in urlopen
    response = self._make_request(
        conn,
    ...<10 lines>...
        **response_kw,
    )
  File "C:\Users\Lanuel\Desktop\blaze-project\.venv\Lib\site-packages\urllib3\connectionpool.py", line 536, in _make_request
    self._raise_timeout(err=e, url=url, timeout_value=read_timeout)
    ~~~~~~~~~~~~~~~~~~~^^^^^^^^^^^^^^^^^^^^^^^^^^^^^^^^^^^^^^^^^^^^
  File "C:\Users\Lanuel\Desktop\blaze-project\.venv\Lib\site-packages\urllib3\connectionpool.py", line 367, in _raise_timeout
    raise ReadTimeoutError(
        self, url, f"Read timed out. (read timeout={timeout_value})"
    ) from err
urllib3.exceptions.ReadTimeoutError: TCPKeepAliveHTTPSConnectionPool(host='api.cloudinary.com', port=443): Read timed out. (read timeout=None)

During handling of the above exception, another exception occurred:

Traceback (most recent call last):
  File "C:\Users\Lanuel\Desktop\blaze-project\.venv\Lib\site-packages\django\core\handlers\exception.py", line 55, in inner
    response = get_response(request)
  File "C:\Users\Lanuel\Desktop\blaze-project\.venv\Lib\site-packages\django\core\handlers\base.py", line 197, in _get_response
    response = wrapped_callback(request, *callback_args, **callback_kwargs)
  File "C:\Users\Lanuel\Desktop\blaze-project\.venv\Lib\site-packages\django\contrib\admin\options.py", line 719, in wrapper
    return self.admin_site.admin_view(view)(*args, **kwargs)
           ~~~~~~~~~~~~~~~~~~~~~~~~~~~~~~~~^^^^^^^^^^^^^^^^^
  File "C:\Users\Lanuel\Desktop\blaze-project\.venv\Lib\site-packages\django\utils\decorators.py", line 192, in _view_wrapper
    result = _process_exception(request, e)
  File "C:\Users\Lanuel\Desktop\blaze-project\.venv\Lib\site-packages\django\utils\decorators.py", line 190, in _view_wrapper
    response = view_func(request, *args, **kwargs)
  File "C:\Users\Lanuel\Desktop\blaze-project\.venv\Lib\site-packages\django\views\decorators\cache.py", line 80, in _view_wrapper
    response = view_func(request, *args, **kwargs)
  File "C:\Users\Lanuel\Desktop\blaze-project\.venv\Lib\site-packages\django\contrib\admin\sites.py", line 246, in inner
    return view(request, *args, **kwargs)
  File "C:\Users\Lanuel\Desktop\blaze-project\.venv\Lib\site-packages\django\contrib\admin\options.py", line 1984, in add_view
    return self.changeform_view(request, None, form_url, extra_context)
           ~~~~~~~~~~~~~~~~~~~~^^^^^^^^^^^^^^^^^^^^^^^^^^^^^^^^^^^^^^^^
  File "C:\Users\Lanuel\Desktop\blaze-project\.venv\Lib\site-packages\django\utils\decorators.py", line 48, in _wrapper
    return bound_method(*args, **kwargs)
  File "C:\Users\Lanuel\Desktop\blaze-project\.venv\Lib\site-packages\django\utils\decorators.py", line 192, in _view_wrapper
    result = _process_exception(request, e)
  File "C:\Users\Lanuel\Desktop\blaze-project\.venv\Lib\site-packages\django\utils\decorators.py", line 190, in _view_wrapper
    response = view_func(request, *args, **kwargs)
  File "C:\Users\Lanuel\Desktop\blaze-project\.venv\Lib\site-packages\django\contrib\admin\options.py", line 1843, in changeform_view
    return self._changeform_view(request, object_id, form_url, extra_context)
           ~~~~~~~~~~~~~~~~~~~~~^^^^^^^^^^^^^^^^^^^^^^^^^^^^^^^^^^^^^^^^^^^^^
  File "C:\Users\Lanuel\Desktop\blaze-project\.venv\Lib\site-packages\django\contrib\admin\options.py", line 1894, in _changeform_view
    self.save_model(request, new_object, form, not add)
    ~~~~~~~~~~~~~~~^^^^^^^^^^^^^^^^^^^^^^^^^^^^^^^^^^^^
  File "C:\Users\Lanuel\Desktop\blaze-project\.venv\Lib\site-packages\django\contrib\admin\options.py", line 1314, in save_model
    obj.save()
    ~~~~~~~~^^
  File "C:\Users\Lanuel\Desktop\blaze-project\.venv\Lib\site-packages\django\db\models\base.py", line 902, in save
    self.save_base(
    ~~~~~~~~~~~~~~^
        using=using,
        ^^^^^^^^^^^^
    ...<2 lines>...
        update_fields=update_fields,
        ^^^^^^^^^^^^^^^^^^^^^^^^^^^^
    )
    ^
  File "C:\Users\Lanuel\Desktop\blaze-project\.venv\Lib\site-packages\django\db\models\base.py", line 1008, in save_base
    updated = self._save_table(
        raw,
    ...<4 lines>...
        update_fields,
    )
  File "C:\Users\Lanuel\Desktop\blaze-project\.venv\Lib\site-packages\django\db\models\base.py", line 1169, in _save_table
    results = self._do_insert(
        cls._base_manager, using, fields, returning_fields, raw
    )
  File "C:\Users\Lanuel\Desktop\blaze-project\.venv\Lib\site-packages\django\db\models\base.py", line 1210, in _do_insert
    return manager._insert(
           ~~~~~~~~~~~~~~~^
        [self],
        ^^^^^^^
    ...<3 lines>...
        raw=raw,
        ^^^^^^^^
    )
    ^
  File "C:\Users\Lanuel\Desktop\blaze-project\.venv\Lib\site-packages\django\db\models\manager.py", line 87, in manager_method
    return getattr(self.get_queryset(), name)(*args, **kwargs)
           ~~~~~~~~~~~~~~~~~~~~~~~~~~~~~~~~~~^^^^^^^^^^^^^^^^^
  File "C:\Users\Lanuel\Desktop\blaze-project\.venv\Lib\site-packages\django\db\models\query.py", line 1854, in _insert
    return query.get_compiler(using=using).execute_sql(returning_fields)
           ~~~~~~~~~~~~~~~~~~~~~~~~~~~~~~~~~~~~~~~~~~~^^^^^^^^^^^^^^^^^^
  File "C:\Users\Lanuel\Desktop\blaze-project\.venv\Lib\site-packages\django\db\models\sql\compiler.py", line 1880, in execute_sql
    for sql, params in self.as_sql():
                       ~~~~~~~~~~~^^
  File "C:\Users\Lanuel\Desktop\blaze-project\.venv\Lib\site-packages\django\db\models\sql\compiler.py", line 1805, in as_sql
    self.prepare_value(field, self.pre_save_val(field, obj))
                              ~~~~~~~~~~~~~~~~~^^^^^^^^^^^^
  File "C:\Users\Lanuel\Desktop\blaze-project\.venv\Lib\site-packages\django\db\models\sql\compiler.py", line 1749, in pre_save_val
    return field.pre_save(obj, add=True)
           ~~~~~~~~~~~~~~^^^^^^^^^^^^^^^
  File "C:\Users\Lanuel\Desktop\blaze-project\.venv\Lib\site-packages\cloudinary\models.py", line 112, in pre_save
    instance_value = uploader.upload_resource(value, **options)
  File "C:\Users\Lanuel\Desktop\blaze-project\.venv\Lib\site-packages\cloudinary\uploader.py", line 253, in upload_resource
    result = upload_func(file, **options)
  File "C:\Users\Lanuel\Desktop\blaze-project\.venv\Lib\site-packages\cloudinary\uploader.py", line 198, in upload
    return call_cacheable_api("upload", params, file=file, **options)
  File "C:\Users\Lanuel\Desktop\blaze-project\.venv\Lib\site-packages\cloudinary\uploader.py", line 834, in call_cacheable_api
    result = call_api(action, params, http_headers, return_error, unsigned, file, timeout, **options)
  File "C:\Users\Lanuel\Desktop\blaze-project\.venv\Lib\site-packages\cloudinary\uploader.py", line 905, in call_api
    raise Error("Unexpected error - {0!r}".format(e))
cloudinary.exceptions.Error: Unexpected error - ReadTimeoutError("TCPKeepAliveHTTPSConnectionPool(host='api.cloudinary.com', port=443): Read timed out. (read timeout=None)")
[2025-06-02 21:24:30,036] ERROR django.server: "POST /3vablazin/a_home/icon/add/ HTTP/1.1" 500 356213
[2025-06-02 21:26:45,361] ERROR django.request: Internal Server Error: /icon/0032c40a-34d8-4f38-b4e5-594b55fa0078/
Traceback (most recent call last):
  File "C:\Users\Lanuel\Desktop\blaze-project\.venv\Lib\site-packages\django\template\backends\django.py", line 107, in render
    return self.template.render(context)
           ~~~~~~~~~~~~~~~~~~~~^^^^^^^^^
  File "C:\Users\Lanuel\Desktop\blaze-project\.venv\Lib\site-packages\django\template\base.py", line 171, in render
    return self._render(context)
           ~~~~~~~~~~~~^^^^^^^^^
  File "C:\Users\Lanuel\Desktop\blaze-project\.venv\Lib\site-packages\django\template\base.py", line 163, in _render
    return self.nodelist.render(context)
           ~~~~~~~~~~~~~~~~~~~~^^^^^^^^^
  File "C:\Users\Lanuel\Desktop\blaze-project\.venv\Lib\site-packages\django\template\base.py", line 1016, in render
    return SafeString("".join([node.render_annotated(context) for node in self]))
                               ~~~~~~~~~~~~~~~~~~~~~^^^^^^^^^
  File "C:\Users\Lanuel\Desktop\blaze-project\.venv\Lib\site-packages\django\template\base.py", line 977, in render_annotated
    return self.render(context)
           ~~~~~~~~~~~^^^^^^^^^
  File "C:\Users\Lanuel\Desktop\blaze-project\.venv\Lib\site-packages\django\template\loader_tags.py", line 159, in render
    return compiled_parent._render(context)
           ~~~~~~~~~~~~~~~~~~~~~~~^^^^^^^^^
  File "C:\Users\Lanuel\Desktop\blaze-project\.venv\Lib\site-packages\django\template\base.py", line 163, in _render
    return self.nodelist.render(context)
           ~~~~~~~~~~~~~~~~~~~~^^^^^^^^^
  File "C:\Users\Lanuel\Desktop\blaze-project\.venv\Lib\site-packages\django\template\base.py", line 1016, in render
    return SafeString("".join([node.render_annotated(context) for node in self]))
                               ~~~~~~~~~~~~~~~~~~~~~^^^^^^^^^
  File "C:\Users\Lanuel\Desktop\blaze-project\.venv\Lib\site-packages\django\template\base.py", line 977, in render_annotated
    return self.render(context)
           ~~~~~~~~~~~^^^^^^^^^
  File "C:\Users\Lanuel\Desktop\blaze-project\.venv\Lib\site-packages\django\template\loader_tags.py", line 65, in render
    result = block.nodelist.render(context)
  File "C:\Users\Lanuel\Desktop\blaze-project\.venv\Lib\site-packages\django\template\base.py", line 1016, in render
    return SafeString("".join([node.render_annotated(context) for node in self]))
                               ~~~~~~~~~~~~~~~~~~~~~^^^^^^^^^
  File "C:\Users\Lanuel\Desktop\blaze-project\.venv\Lib\site-packages\django\template\base.py", line 977, in render_annotated
    return self.render(context)
           ~~~~~~~~~~~^^^^^^^^^
  File "C:\Users\Lanuel\Desktop\blaze-project\.venv\Lib\site-packages\django\template\loader_tags.py", line 199, in render
    template = context.template.engine.select_template(template_name)
  File "C:\Users\Lanuel\Desktop\blaze-project\.venv\Lib\site-packages\django\template\engine.py", line 214, in select_template
    raise TemplateDoesNotExist(", ".join(not_found))
django.template.exceptions.TemplateDoesNotExist: icons/partials/t-shirt design.html

The above exception was the direct cause of the following exception:

Traceback (most recent call last):
  File "C:\Users\Lanuel\Desktop\blaze-project\.venv\Lib\site-packages\django\core\handlers\exception.py", line 55, in inner
    response = get_response(request)
  File "C:\Users\Lanuel\Desktop\blaze-project\.venv\Lib\site-packages\django\core\handlers\base.py", line 197, in _get_response
    response = wrapped_callback(request, *callback_args, **callback_kwargs)
  File "C:\Users\Lanuel\Desktop\blaze-project\a_home\views.py", line 35, in icon_detail
    return render(request, 'icons/icon_detail.html', context)
  File "C:\Users\Lanuel\Desktop\blaze-project\.venv\Lib\site-packages\django\shortcuts.py", line 25, in render
    content = loader.render_to_string(template_name, context, request, using=using)
  File "C:\Users\Lanuel\Desktop\blaze-project\.venv\Lib\site-packages\django\template\loader.py", line 62, in render_to_string
    return template.render(context, request)
           ~~~~~~~~~~~~~~~^^^^^^^^^^^^^^^^^^
  File "C:\Users\Lanuel\Desktop\blaze-project\.venv\Lib\site-packages\django\template\backends\django.py", line 109, in render
    reraise(exc, self.backend)
    ~~~~~~~^^^^^^^^^^^^^^^^^^^
  File "C:\Users\Lanuel\Desktop\blaze-project\.venv\Lib\site-packages\django\template\backends\django.py", line 130, in reraise
    raise new from exc
django.template.exceptions.TemplateDoesNotExist: icons/partials/t-shirt design.html
[2025-06-02 21:26:45,896] ERROR django.server: "GET /icon/0032c40a-34d8-4f38-b4e5-594b55fa0078/ HTTP/1.1" 500 161361
